2025-03-10 19:46:49,796 - uvicorn.error - ERROR - /Users/jskuratowicz/PersonalProjects/NL2SQL-agent/backend/venv/lib/python3.11/site-packages/uvicorn/protocols/http/h11_impl.py:413 - Exception in ASGI application
Traceback (most recent call last):
  File "/Users/jskuratowicz/PersonalProjects/NL2SQL-agent/backend/venv/lib/python3.11/site-packages/starlette/middleware/base.py", line 78, in call_next
    message = await recv_stream.receive()
              ^^^^^^^^^^^^^^^^^^^^^^^^^^^
  File "/Users/jskuratowicz/PersonalProjects/NL2SQL-agent/backend/venv/lib/python3.11/site-packages/anyio/streams/memory.py", line 98, in receive
    return self.receive_nowait()
           ^^^^^^^^^^^^^^^^^^^^^
  File "/Users/jskuratowicz/PersonalProjects/NL2SQL-agent/backend/venv/lib/python3.11/site-packages/anyio/streams/memory.py", line 91, in receive_nowait
    raise EndOfStream
anyio.EndOfStream

During handling of the above exception, another exception occurred:

Traceback (most recent call last):
  File "/Users/jskuratowicz/PersonalProjects/NL2SQL-agent/backend/app/main.py", line 40, in dispatch
    response = await call_next(request)
               ^^^^^^^^^^^^^^^^^^^^^^^^
  File "/Users/jskuratowicz/PersonalProjects/NL2SQL-agent/backend/venv/lib/python3.11/site-packages/starlette/middleware/base.py", line 84, in call_next
    raise app_exc
  File "/Users/jskuratowicz/PersonalProjects/NL2SQL-agent/backend/venv/lib/python3.11/site-packages/starlette/middleware/base.py", line 70, in coro
    await self.app(scope, receive_or_disconnect, send_no_error)
  File "/Users/jskuratowicz/PersonalProjects/NL2SQL-agent/backend/venv/lib/python3.11/site-packages/starlette/middleware/exceptions.py", line 79, in __call__
    raise exc
  File "/Users/jskuratowicz/PersonalProjects/NL2SQL-agent/backend/venv/lib/python3.11/site-packages/starlette/middleware/exceptions.py", line 68, in __call__
    await self.app(scope, receive, sender)
  File "/Users/jskuratowicz/PersonalProjects/NL2SQL-agent/backend/venv/lib/python3.11/site-packages/fastapi/middleware/asyncexitstack.py", line 20, in __call__
    raise e
  File "/Users/jskuratowicz/PersonalProjects/NL2SQL-agent/backend/venv/lib/python3.11/site-packages/fastapi/middleware/asyncexitstack.py", line 17, in __call__
    await self.app(scope, receive, send)
  File "/Users/jskuratowicz/PersonalProjects/NL2SQL-agent/backend/venv/lib/python3.11/site-packages/starlette/routing.py", line 718, in __call__
    await route.handle(scope, receive, send)
  File "/Users/jskuratowicz/PersonalProjects/NL2SQL-agent/backend/venv/lib/python3.11/site-packages/starlette/routing.py", line 276, in handle
    await self.app(scope, receive, send)
  File "/Users/jskuratowicz/PersonalProjects/NL2SQL-agent/backend/venv/lib/python3.11/site-packages/starlette/routing.py", line 66, in app
    response = await func(request)
               ^^^^^^^^^^^^^^^^^^^
  File "/Users/jskuratowicz/PersonalProjects/NL2SQL-agent/backend/venv/lib/python3.11/site-packages/fastapi/routing.py", line 274, in app
    raw_response = await run_endpoint_function(
                   ^^^^^^^^^^^^^^^^^^^^^^^^^^^^
  File "/Users/jskuratowicz/PersonalProjects/NL2SQL-agent/backend/venv/lib/python3.11/site-packages/fastapi/routing.py", line 191, in run_endpoint_function
    return await dependant.call(**values)
           ^^^^^^^^^^^^^^^^^^^^^^^^^^^^^^
  File "/Users/jskuratowicz/PersonalProjects/NL2SQL-agent/backend/app/utils/performance.py", line 51, in wrapper
    result = await func(*args, **kwargs)
             ^^^^^^^^^^^^^^^^^^^^^^^^^^^
  File "/Users/jskuratowicz/PersonalProjects/NL2SQL-agent/backend/app/api/routes.py", line 47, in get_tables
    logger.info(f"Listing tables for demo phase: {demo_phase}", extra={"request_id": request_id})
  File "/Library/Frameworks/Python.framework/Versions/3.11/lib/python3.11/logging/__init__.py", line 1489, in info
    self._log(INFO, msg, args, **kwargs)
  File "/Library/Frameworks/Python.framework/Versions/3.11/lib/python3.11/logging/__init__.py", line 1632, in _log
    record = self.makeRecord(self.name, level, fn, lno, msg, args,
             ^^^^^^^^^^^^^^^^^^^^^^^^^^^^^^^^^^^^^^^^^^^^^^^^^^^^^
  File "/Library/Frameworks/Python.framework/Versions/3.11/lib/python3.11/logging/__init__.py", line 1606, in makeRecord
    raise KeyError("Attempt to overwrite %r in LogRecord" % key)
KeyError: "Attempt to overwrite 'request_id' in LogRecord"

During handling of the above exception, another exception occurred:

Traceback (most recent call last):
  File "/Users/jskuratowicz/PersonalProjects/NL2SQL-agent/backend/venv/lib/python3.11/site-packages/uvicorn/protocols/http/h11_impl.py", line 408, in run_asgi
    result = await app(  # type: ignore[func-returns-value]
             ^^^^^^^^^^^^^^^^^^^^^^^^^^^^^^^^^^^^^^^^^^^^^^
  File "/Users/jskuratowicz/PersonalProjects/NL2SQL-agent/backend/venv/lib/python3.11/site-packages/uvicorn/middleware/proxy_headers.py", line 84, in __call__
    return await self.app(scope, receive, send)
           ^^^^^^^^^^^^^^^^^^^^^^^^^^^^^^^^^^^^
  File "/Users/jskuratowicz/PersonalProjects/NL2SQL-agent/backend/venv/lib/python3.11/site-packages/fastapi/applications.py", line 1106, in __call__
    await super().__call__(scope, receive, send)
  File "/Users/jskuratowicz/PersonalProjects/NL2SQL-agent/backend/venv/lib/python3.11/site-packages/starlette/applications.py", line 122, in __call__
    await self.middleware_stack(scope, receive, send)
  File "/Users/jskuratowicz/PersonalProjects/NL2SQL-agent/backend/venv/lib/python3.11/site-packages/starlette/middleware/errors.py", line 184, in __call__
    raise exc
  File "/Users/jskuratowicz/PersonalProjects/NL2SQL-agent/backend/venv/lib/python3.11/site-packages/starlette/middleware/errors.py", line 162, in __call__
    await self.app(scope, receive, _send)
  File "/Users/jskuratowicz/PersonalProjects/NL2SQL-agent/backend/venv/lib/python3.11/site-packages/starlette/middleware/cors.py", line 91, in __call__
    await self.simple_response(scope, receive, send, request_headers=headers)
  File "/Users/jskuratowicz/PersonalProjects/NL2SQL-agent/backend/venv/lib/python3.11/site-packages/starlette/middleware/cors.py", line 146, in simple_response
    await self.app(scope, receive, send)
  File "/Users/jskuratowicz/PersonalProjects/NL2SQL-agent/backend/venv/lib/python3.11/site-packages/starlette/middleware/base.py", line 108, in __call__
    response = await self.dispatch_func(request, call_next)
               ^^^^^^^^^^^^^^^^^^^^^^^^^^^^^^^^^^^^^^^^^^^^
  File "/Users/jskuratowicz/PersonalProjects/NL2SQL-agent/backend/app/main.py", line 65, in dispatch
    logger.exception(
  File "/Library/Frameworks/Python.framework/Versions/3.11/lib/python3.11/logging/__init__.py", line 1524, in exception
    self.error(msg, *args, exc_info=exc_info, **kwargs)
  File "/Library/Frameworks/Python.framework/Versions/3.11/lib/python3.11/logging/__init__.py", line 1518, in error
    self._log(ERROR, msg, args, **kwargs)
  File "/Library/Frameworks/Python.framework/Versions/3.11/lib/python3.11/logging/__init__.py", line 1632, in _log
    record = self.makeRecord(self.name, level, fn, lno, msg, args,
             ^^^^^^^^^^^^^^^^^^^^^^^^^^^^^^^^^^^^^^^^^^^^^^^^^^^^^
  File "/Library/Frameworks/Python.framework/Versions/3.11/lib/python3.11/logging/__init__.py", line 1606, in makeRecord
    raise KeyError("Attempt to overwrite %r in LogRecord" % key)
KeyError: "Attempt to overwrite 'request_id' in LogRecord"
2025-03-10 19:46:49,801 - uvicorn.error - ERROR - /Users/jskuratowicz/PersonalProjects/NL2SQL-agent/backend/venv/lib/python3.11/site-packages/uvicorn/protocols/http/h11_impl.py:413 - Exception in ASGI application
Traceback (most recent call last):
  File "/Users/jskuratowicz/PersonalProjects/NL2SQL-agent/backend/venv/lib/python3.11/site-packages/starlette/middleware/base.py", line 78, in call_next
    message = await recv_stream.receive()
              ^^^^^^^^^^^^^^^^^^^^^^^^^^^
  File "/Users/jskuratowicz/PersonalProjects/NL2SQL-agent/backend/venv/lib/python3.11/site-packages/anyio/streams/memory.py", line 98, in receive
    return self.receive_nowait()
           ^^^^^^^^^^^^^^^^^^^^^
  File "/Users/jskuratowicz/PersonalProjects/NL2SQL-agent/backend/venv/lib/python3.11/site-packages/anyio/streams/memory.py", line 91, in receive_nowait
    raise EndOfStream
anyio.EndOfStream

During handling of the above exception, another exception occurred:

Traceback (most recent call last):
  File "/Users/jskuratowicz/PersonalProjects/NL2SQL-agent/backend/app/main.py", line 40, in dispatch
    response = await call_next(request)
               ^^^^^^^^^^^^^^^^^^^^^^^^
  File "/Users/jskuratowicz/PersonalProjects/NL2SQL-agent/backend/venv/lib/python3.11/site-packages/starlette/middleware/base.py", line 84, in call_next
    raise app_exc
  File "/Users/jskuratowicz/PersonalProjects/NL2SQL-agent/backend/venv/lib/python3.11/site-packages/starlette/middleware/base.py", line 70, in coro
    await self.app(scope, receive_or_disconnect, send_no_error)
  File "/Users/jskuratowicz/PersonalProjects/NL2SQL-agent/backend/venv/lib/python3.11/site-packages/starlette/middleware/exceptions.py", line 79, in __call__
    raise exc
  File "/Users/jskuratowicz/PersonalProjects/NL2SQL-agent/backend/venv/lib/python3.11/site-packages/starlette/middleware/exceptions.py", line 68, in __call__
    await self.app(scope, receive, sender)
  File "/Users/jskuratowicz/PersonalProjects/NL2SQL-agent/backend/venv/lib/python3.11/site-packages/fastapi/middleware/asyncexitstack.py", line 20, in __call__
    raise e
  File "/Users/jskuratowicz/PersonalProjects/NL2SQL-agent/backend/venv/lib/python3.11/site-packages/fastapi/middleware/asyncexitstack.py", line 17, in __call__
    await self.app(scope, receive, send)
  File "/Users/jskuratowicz/PersonalProjects/NL2SQL-agent/backend/venv/lib/python3.11/site-packages/starlette/routing.py", line 718, in __call__
    await route.handle(scope, receive, send)
  File "/Users/jskuratowicz/PersonalProjects/NL2SQL-agent/backend/venv/lib/python3.11/site-packages/starlette/routing.py", line 276, in handle
    await self.app(scope, receive, send)
  File "/Users/jskuratowicz/PersonalProjects/NL2SQL-agent/backend/venv/lib/python3.11/site-packages/starlette/routing.py", line 66, in app
    response = await func(request)
               ^^^^^^^^^^^^^^^^^^^
  File "/Users/jskuratowicz/PersonalProjects/NL2SQL-agent/backend/venv/lib/python3.11/site-packages/fastapi/routing.py", line 274, in app
    raw_response = await run_endpoint_function(
                   ^^^^^^^^^^^^^^^^^^^^^^^^^^^^
  File "/Users/jskuratowicz/PersonalProjects/NL2SQL-agent/backend/venv/lib/python3.11/site-packages/fastapi/routing.py", line 191, in run_endpoint_function
    return await dependant.call(**values)
           ^^^^^^^^^^^^^^^^^^^^^^^^^^^^^^
  File "/Users/jskuratowicz/PersonalProjects/NL2SQL-agent/backend/app/utils/performance.py", line 51, in wrapper
    result = await func(*args, **kwargs)
             ^^^^^^^^^^^^^^^^^^^^^^^^^^^
  File "/Users/jskuratowicz/PersonalProjects/NL2SQL-agent/backend/app/api/routes.py", line 47, in get_tables
    logger.info(f"Listing tables for demo phase: {demo_phase}", extra={"request_id": request_id})
  File "/Library/Frameworks/Python.framework/Versions/3.11/lib/python3.11/logging/__init__.py", line 1489, in info
    self._log(INFO, msg, args, **kwargs)
  File "/Library/Frameworks/Python.framework/Versions/3.11/lib/python3.11/logging/__init__.py", line 1632, in _log
    record = self.makeRecord(self.name, level, fn, lno, msg, args,
             ^^^^^^^^^^^^^^^^^^^^^^^^^^^^^^^^^^^^^^^^^^^^^^^^^^^^^
  File "/Library/Frameworks/Python.framework/Versions/3.11/lib/python3.11/logging/__init__.py", line 1606, in makeRecord
    raise KeyError("Attempt to overwrite %r in LogRecord" % key)
KeyError: "Attempt to overwrite 'request_id' in LogRecord"

During handling of the above exception, another exception occurred:

Traceback (most recent call last):
  File "/Users/jskuratowicz/PersonalProjects/NL2SQL-agent/backend/venv/lib/python3.11/site-packages/uvicorn/protocols/http/h11_impl.py", line 408, in run_asgi
    result = await app(  # type: ignore[func-returns-value]
             ^^^^^^^^^^^^^^^^^^^^^^^^^^^^^^^^^^^^^^^^^^^^^^
  File "/Users/jskuratowicz/PersonalProjects/NL2SQL-agent/backend/venv/lib/python3.11/site-packages/uvicorn/middleware/proxy_headers.py", line 84, in __call__
    return await self.app(scope, receive, send)
           ^^^^^^^^^^^^^^^^^^^^^^^^^^^^^^^^^^^^
  File "/Users/jskuratowicz/PersonalProjects/NL2SQL-agent/backend/venv/lib/python3.11/site-packages/fastapi/applications.py", line 1106, in __call__
    await super().__call__(scope, receive, send)
  File "/Users/jskuratowicz/PersonalProjects/NL2SQL-agent/backend/venv/lib/python3.11/site-packages/starlette/applications.py", line 122, in __call__
    await self.middleware_stack(scope, receive, send)
  File "/Users/jskuratowicz/PersonalProjects/NL2SQL-agent/backend/venv/lib/python3.11/site-packages/starlette/middleware/errors.py", line 184, in __call__
    raise exc
  File "/Users/jskuratowicz/PersonalProjects/NL2SQL-agent/backend/venv/lib/python3.11/site-packages/starlette/middleware/errors.py", line 162, in __call__
    await self.app(scope, receive, _send)
  File "/Users/jskuratowicz/PersonalProjects/NL2SQL-agent/backend/venv/lib/python3.11/site-packages/starlette/middleware/cors.py", line 91, in __call__
    await self.simple_response(scope, receive, send, request_headers=headers)
  File "/Users/jskuratowicz/PersonalProjects/NL2SQL-agent/backend/venv/lib/python3.11/site-packages/starlette/middleware/cors.py", line 146, in simple_response
    await self.app(scope, receive, send)
  File "/Users/jskuratowicz/PersonalProjects/NL2SQL-agent/backend/venv/lib/python3.11/site-packages/starlette/middleware/base.py", line 108, in __call__
    response = await self.dispatch_func(request, call_next)
               ^^^^^^^^^^^^^^^^^^^^^^^^^^^^^^^^^^^^^^^^^^^^
  File "/Users/jskuratowicz/PersonalProjects/NL2SQL-agent/backend/app/main.py", line 65, in dispatch
    logger.exception(
  File "/Library/Frameworks/Python.framework/Versions/3.11/lib/python3.11/logging/__init__.py", line 1524, in exception
    self.error(msg, *args, exc_info=exc_info, **kwargs)
  File "/Library/Frameworks/Python.framework/Versions/3.11/lib/python3.11/logging/__init__.py", line 1518, in error
    self._log(ERROR, msg, args, **kwargs)
  File "/Library/Frameworks/Python.framework/Versions/3.11/lib/python3.11/logging/__init__.py", line 1632, in _log
    record = self.makeRecord(self.name, level, fn, lno, msg, args,
             ^^^^^^^^^^^^^^^^^^^^^^^^^^^^^^^^^^^^^^^^^^^^^^^^^^^^^
  File "/Library/Frameworks/Python.framework/Versions/3.11/lib/python3.11/logging/__init__.py", line 1606, in makeRecord
    raise KeyError("Attempt to overwrite %r in LogRecord" % key)
KeyError: "Attempt to overwrite 'request_id' in LogRecord"
2025-03-10 19:49:58,507 - app.core.logging_config - ERROR - /Users/jskuratowicz/PersonalProjects/NL2SQL-agent/backend/app/main.py:64 - Request failed: GET /api/tables
Traceback (most recent call last):
  File "/Users/jskuratowicz/PersonalProjects/NL2SQL-agent/backend/venv/lib/python3.11/site-packages/starlette/middleware/base.py", line 78, in call_next
    message = await recv_stream.receive()
              ^^^^^^^^^^^^^^^^^^^^^^^^^^^
  File "/Users/jskuratowicz/PersonalProjects/NL2SQL-agent/backend/venv/lib/python3.11/site-packages/anyio/streams/memory.py", line 98, in receive
    return self.receive_nowait()
           ^^^^^^^^^^^^^^^^^^^^^
  File "/Users/jskuratowicz/PersonalProjects/NL2SQL-agent/backend/venv/lib/python3.11/site-packages/anyio/streams/memory.py", line 91, in receive_nowait
    raise EndOfStream
anyio.EndOfStream

During handling of the above exception, another exception occurred:

Traceback (most recent call last):
  File "/Users/jskuratowicz/PersonalProjects/NL2SQL-agent/backend/app/main.py", line 40, in dispatch
    response = await call_next(request)
               ^^^^^^^^^^^^^^^^^^^^^^^^
  File "/Users/jskuratowicz/PersonalProjects/NL2SQL-agent/backend/venv/lib/python3.11/site-packages/starlette/middleware/base.py", line 84, in call_next
    raise app_exc
  File "/Users/jskuratowicz/PersonalProjects/NL2SQL-agent/backend/venv/lib/python3.11/site-packages/starlette/middleware/base.py", line 70, in coro
    await self.app(scope, receive_or_disconnect, send_no_error)
  File "/Users/jskuratowicz/PersonalProjects/NL2SQL-agent/backend/venv/lib/python3.11/site-packages/starlette/middleware/exceptions.py", line 79, in __call__
    raise exc
  File "/Users/jskuratowicz/PersonalProjects/NL2SQL-agent/backend/venv/lib/python3.11/site-packages/starlette/middleware/exceptions.py", line 68, in __call__
    await self.app(scope, receive, sender)
  File "/Users/jskuratowicz/PersonalProjects/NL2SQL-agent/backend/venv/lib/python3.11/site-packages/fastapi/middleware/asyncexitstack.py", line 20, in __call__
    raise e
  File "/Users/jskuratowicz/PersonalProjects/NL2SQL-agent/backend/venv/lib/python3.11/site-packages/fastapi/middleware/asyncexitstack.py", line 17, in __call__
    await self.app(scope, receive, send)
  File "/Users/jskuratowicz/PersonalProjects/NL2SQL-agent/backend/venv/lib/python3.11/site-packages/starlette/routing.py", line 718, in __call__
    await route.handle(scope, receive, send)
  File "/Users/jskuratowicz/PersonalProjects/NL2SQL-agent/backend/venv/lib/python3.11/site-packages/starlette/routing.py", line 276, in handle
    await self.app(scope, receive, send)
  File "/Users/jskuratowicz/PersonalProjects/NL2SQL-agent/backend/venv/lib/python3.11/site-packages/starlette/routing.py", line 66, in app
    response = await func(request)
               ^^^^^^^^^^^^^^^^^^^
  File "/Users/jskuratowicz/PersonalProjects/NL2SQL-agent/backend/venv/lib/python3.11/site-packages/fastapi/routing.py", line 274, in app
    raw_response = await run_endpoint_function(
                   ^^^^^^^^^^^^^^^^^^^^^^^^^^^^
  File "/Users/jskuratowicz/PersonalProjects/NL2SQL-agent/backend/venv/lib/python3.11/site-packages/fastapi/routing.py", line 191, in run_endpoint_function
    return await dependant.call(**values)
           ^^^^^^^^^^^^^^^^^^^^^^^^^^^^^^
  File "/Users/jskuratowicz/PersonalProjects/NL2SQL-agent/backend/app/utils/performance.py", line 51, in wrapper
    result = await func(*args, **kwargs)
             ^^^^^^^^^^^^^^^^^^^^^^^^^^^
  File "/Users/jskuratowicz/PersonalProjects/NL2SQL-agent/backend/app/api/routes.py", line 47, in get_tables
    logger.info(f"Listing tables for demo phase: {demo_phase}", extra={"request_id": request_id})
  File "/Library/Frameworks/Python.framework/Versions/3.11/lib/python3.11/logging/__init__.py", line 1489, in info
    self._log(INFO, msg, args, **kwargs)
  File "/Library/Frameworks/Python.framework/Versions/3.11/lib/python3.11/logging/__init__.py", line 1632, in _log
    record = self.makeRecord(self.name, level, fn, lno, msg, args,
             ^^^^^^^^^^^^^^^^^^^^^^^^^^^^^^^^^^^^^^^^^^^^^^^^^^^^^
  File "/Library/Frameworks/Python.framework/Versions/3.11/lib/python3.11/logging/__init__.py", line 1606, in makeRecord
    raise KeyError("Attempt to overwrite %r in LogRecord" % key)
KeyError: "Attempt to overwrite 'request_id' in LogRecord"
2025-03-10 19:49:58,533 - uvicorn.error - ERROR - /Users/jskuratowicz/PersonalProjects/NL2SQL-agent/backend/venv/lib/python3.11/site-packages/uvicorn/protocols/http/h11_impl.py:413 - Exception in ASGI application
Traceback (most recent call last):
  File "/Users/jskuratowicz/PersonalProjects/NL2SQL-agent/backend/venv/lib/python3.11/site-packages/starlette/middleware/base.py", line 78, in call_next
    message = await recv_stream.receive()
              ^^^^^^^^^^^^^^^^^^^^^^^^^^^
  File "/Users/jskuratowicz/PersonalProjects/NL2SQL-agent/backend/venv/lib/python3.11/site-packages/anyio/streams/memory.py", line 98, in receive
    return self.receive_nowait()
           ^^^^^^^^^^^^^^^^^^^^^
  File "/Users/jskuratowicz/PersonalProjects/NL2SQL-agent/backend/venv/lib/python3.11/site-packages/anyio/streams/memory.py", line 91, in receive_nowait
    raise EndOfStream
anyio.EndOfStream

During handling of the above exception, another exception occurred:

Traceback (most recent call last):
  File "/Users/jskuratowicz/PersonalProjects/NL2SQL-agent/backend/venv/lib/python3.11/site-packages/uvicorn/protocols/http/h11_impl.py", line 408, in run_asgi
    result = await app(  # type: ignore[func-returns-value]
             ^^^^^^^^^^^^^^^^^^^^^^^^^^^^^^^^^^^^^^^^^^^^^^
  File "/Users/jskuratowicz/PersonalProjects/NL2SQL-agent/backend/venv/lib/python3.11/site-packages/uvicorn/middleware/proxy_headers.py", line 84, in __call__
    return await self.app(scope, receive, send)
           ^^^^^^^^^^^^^^^^^^^^^^^^^^^^^^^^^^^^
  File "/Users/jskuratowicz/PersonalProjects/NL2SQL-agent/backend/venv/lib/python3.11/site-packages/fastapi/applications.py", line 1106, in __call__
    await super().__call__(scope, receive, send)
  File "/Users/jskuratowicz/PersonalProjects/NL2SQL-agent/backend/venv/lib/python3.11/site-packages/starlette/applications.py", line 122, in __call__
    await self.middleware_stack(scope, receive, send)
  File "/Users/jskuratowicz/PersonalProjects/NL2SQL-agent/backend/venv/lib/python3.11/site-packages/starlette/middleware/errors.py", line 184, in __call__
    raise exc
  File "/Users/jskuratowicz/PersonalProjects/NL2SQL-agent/backend/venv/lib/python3.11/site-packages/starlette/middleware/errors.py", line 162, in __call__
    await self.app(scope, receive, _send)
  File "/Users/jskuratowicz/PersonalProjects/NL2SQL-agent/backend/venv/lib/python3.11/site-packages/starlette/middleware/cors.py", line 91, in __call__
    await self.simple_response(scope, receive, send, request_headers=headers)
  File "/Users/jskuratowicz/PersonalProjects/NL2SQL-agent/backend/venv/lib/python3.11/site-packages/starlette/middleware/cors.py", line 146, in simple_response
    await self.app(scope, receive, send)
  File "/Users/jskuratowicz/PersonalProjects/NL2SQL-agent/backend/venv/lib/python3.11/site-packages/starlette/middleware/base.py", line 108, in __call__
    response = await self.dispatch_func(request, call_next)
               ^^^^^^^^^^^^^^^^^^^^^^^^^^^^^^^^^^^^^^^^^^^^
  File "/Users/jskuratowicz/PersonalProjects/NL2SQL-agent/backend/app/main.py", line 40, in dispatch
    response = await call_next(request)
               ^^^^^^^^^^^^^^^^^^^^^^^^
  File "/Users/jskuratowicz/PersonalProjects/NL2SQL-agent/backend/venv/lib/python3.11/site-packages/starlette/middleware/base.py", line 84, in call_next
    raise app_exc
  File "/Users/jskuratowicz/PersonalProjects/NL2SQL-agent/backend/venv/lib/python3.11/site-packages/starlette/middleware/base.py", line 70, in coro
    await self.app(scope, receive_or_disconnect, send_no_error)
  File "/Users/jskuratowicz/PersonalProjects/NL2SQL-agent/backend/venv/lib/python3.11/site-packages/starlette/middleware/exceptions.py", line 79, in __call__
    raise exc
  File "/Users/jskuratowicz/PersonalProjects/NL2SQL-agent/backend/venv/lib/python3.11/site-packages/starlette/middleware/exceptions.py", line 68, in __call__
    await self.app(scope, receive, sender)
  File "/Users/jskuratowicz/PersonalProjects/NL2SQL-agent/backend/venv/lib/python3.11/site-packages/fastapi/middleware/asyncexitstack.py", line 20, in __call__
    raise e
  File "/Users/jskuratowicz/PersonalProjects/NL2SQL-agent/backend/venv/lib/python3.11/site-packages/fastapi/middleware/asyncexitstack.py", line 17, in __call__
    await self.app(scope, receive, send)
  File "/Users/jskuratowicz/PersonalProjects/NL2SQL-agent/backend/venv/lib/python3.11/site-packages/starlette/routing.py", line 718, in __call__
    await route.handle(scope, receive, send)
  File "/Users/jskuratowicz/PersonalProjects/NL2SQL-agent/backend/venv/lib/python3.11/site-packages/starlette/routing.py", line 276, in handle
    await self.app(scope, receive, send)
  File "/Users/jskuratowicz/PersonalProjects/NL2SQL-agent/backend/venv/lib/python3.11/site-packages/starlette/routing.py", line 66, in app
    response = await func(request)
               ^^^^^^^^^^^^^^^^^^^
  File "/Users/jskuratowicz/PersonalProjects/NL2SQL-agent/backend/venv/lib/python3.11/site-packages/fastapi/routing.py", line 274, in app
    raw_response = await run_endpoint_function(
                   ^^^^^^^^^^^^^^^^^^^^^^^^^^^^
  File "/Users/jskuratowicz/PersonalProjects/NL2SQL-agent/backend/venv/lib/python3.11/site-packages/fastapi/routing.py", line 191, in run_endpoint_function
    return await dependant.call(**values)
           ^^^^^^^^^^^^^^^^^^^^^^^^^^^^^^
  File "/Users/jskuratowicz/PersonalProjects/NL2SQL-agent/backend/app/utils/performance.py", line 51, in wrapper
    result = await func(*args, **kwargs)
             ^^^^^^^^^^^^^^^^^^^^^^^^^^^
  File "/Users/jskuratowicz/PersonalProjects/NL2SQL-agent/backend/app/api/routes.py", line 47, in get_tables
    logger.info(f"Listing tables for demo phase: {demo_phase}", extra={"request_id": request_id})
  File "/Library/Frameworks/Python.framework/Versions/3.11/lib/python3.11/logging/__init__.py", line 1489, in info
    self._log(INFO, msg, args, **kwargs)
  File "/Library/Frameworks/Python.framework/Versions/3.11/lib/python3.11/logging/__init__.py", line 1632, in _log
    record = self.makeRecord(self.name, level, fn, lno, msg, args,
             ^^^^^^^^^^^^^^^^^^^^^^^^^^^^^^^^^^^^^^^^^^^^^^^^^^^^^
  File "/Library/Frameworks/Python.framework/Versions/3.11/lib/python3.11/logging/__init__.py", line 1606, in makeRecord
    raise KeyError("Attempt to overwrite %r in LogRecord" % key)
KeyError: "Attempt to overwrite 'request_id' in LogRecord"
2025-03-10 19:49:58,539 - app.core.logging_config - ERROR - /Users/jskuratowicz/PersonalProjects/NL2SQL-agent/backend/app/main.py:64 - Request failed: GET /api/tables
Traceback (most recent call last):
  File "/Users/jskuratowicz/PersonalProjects/NL2SQL-agent/backend/venv/lib/python3.11/site-packages/starlette/middleware/base.py", line 78, in call_next
    message = await recv_stream.receive()
              ^^^^^^^^^^^^^^^^^^^^^^^^^^^
  File "/Users/jskuratowicz/PersonalProjects/NL2SQL-agent/backend/venv/lib/python3.11/site-packages/anyio/streams/memory.py", line 98, in receive
    return self.receive_nowait()
           ^^^^^^^^^^^^^^^^^^^^^
  File "/Users/jskuratowicz/PersonalProjects/NL2SQL-agent/backend/venv/lib/python3.11/site-packages/anyio/streams/memory.py", line 91, in receive_nowait
    raise EndOfStream
anyio.EndOfStream

During handling of the above exception, another exception occurred:

Traceback (most recent call last):
  File "/Users/jskuratowicz/PersonalProjects/NL2SQL-agent/backend/app/main.py", line 40, in dispatch
    response = await call_next(request)
               ^^^^^^^^^^^^^^^^^^^^^^^^
  File "/Users/jskuratowicz/PersonalProjects/NL2SQL-agent/backend/venv/lib/python3.11/site-packages/starlette/middleware/base.py", line 84, in call_next
    raise app_exc
  File "/Users/jskuratowicz/PersonalProjects/NL2SQL-agent/backend/venv/lib/python3.11/site-packages/starlette/middleware/base.py", line 70, in coro
    await self.app(scope, receive_or_disconnect, send_no_error)
  File "/Users/jskuratowicz/PersonalProjects/NL2SQL-agent/backend/venv/lib/python3.11/site-packages/starlette/middleware/exceptions.py", line 79, in __call__
    raise exc
  File "/Users/jskuratowicz/PersonalProjects/NL2SQL-agent/backend/venv/lib/python3.11/site-packages/starlette/middleware/exceptions.py", line 68, in __call__
    await self.app(scope, receive, sender)
  File "/Users/jskuratowicz/PersonalProjects/NL2SQL-agent/backend/venv/lib/python3.11/site-packages/fastapi/middleware/asyncexitstack.py", line 20, in __call__
    raise e
  File "/Users/jskuratowicz/PersonalProjects/NL2SQL-agent/backend/venv/lib/python3.11/site-packages/fastapi/middleware/asyncexitstack.py", line 17, in __call__
    await self.app(scope, receive, send)
  File "/Users/jskuratowicz/PersonalProjects/NL2SQL-agent/backend/venv/lib/python3.11/site-packages/starlette/routing.py", line 718, in __call__
    await route.handle(scope, receive, send)
  File "/Users/jskuratowicz/PersonalProjects/NL2SQL-agent/backend/venv/lib/python3.11/site-packages/starlette/routing.py", line 276, in handle
    await self.app(scope, receive, send)
  File "/Users/jskuratowicz/PersonalProjects/NL2SQL-agent/backend/venv/lib/python3.11/site-packages/starlette/routing.py", line 66, in app
    response = await func(request)
               ^^^^^^^^^^^^^^^^^^^
  File "/Users/jskuratowicz/PersonalProjects/NL2SQL-agent/backend/venv/lib/python3.11/site-packages/fastapi/routing.py", line 274, in app
    raw_response = await run_endpoint_function(
                   ^^^^^^^^^^^^^^^^^^^^^^^^^^^^
  File "/Users/jskuratowicz/PersonalProjects/NL2SQL-agent/backend/venv/lib/python3.11/site-packages/fastapi/routing.py", line 191, in run_endpoint_function
    return await dependant.call(**values)
           ^^^^^^^^^^^^^^^^^^^^^^^^^^^^^^
  File "/Users/jskuratowicz/PersonalProjects/NL2SQL-agent/backend/app/utils/performance.py", line 51, in wrapper
    result = await func(*args, **kwargs)
             ^^^^^^^^^^^^^^^^^^^^^^^^^^^
  File "/Users/jskuratowicz/PersonalProjects/NL2SQL-agent/backend/app/api/routes.py", line 47, in get_tables
    logger.info(f"Listing tables for demo phase: {demo_phase}", extra={"request_id": request_id})
  File "/Library/Frameworks/Python.framework/Versions/3.11/lib/python3.11/logging/__init__.py", line 1489, in info
    self._log(INFO, msg, args, **kwargs)
  File "/Library/Frameworks/Python.framework/Versions/3.11/lib/python3.11/logging/__init__.py", line 1632, in _log
    record = self.makeRecord(self.name, level, fn, lno, msg, args,
             ^^^^^^^^^^^^^^^^^^^^^^^^^^^^^^^^^^^^^^^^^^^^^^^^^^^^^
  File "/Library/Frameworks/Python.framework/Versions/3.11/lib/python3.11/logging/__init__.py", line 1606, in makeRecord
    raise KeyError("Attempt to overwrite %r in LogRecord" % key)
KeyError: "Attempt to overwrite 'request_id' in LogRecord"
2025-03-10 19:49:58,542 - uvicorn.error - ERROR - /Users/jskuratowicz/PersonalProjects/NL2SQL-agent/backend/venv/lib/python3.11/site-packages/uvicorn/protocols/http/h11_impl.py:413 - Exception in ASGI application
Traceback (most recent call last):
  File "/Users/jskuratowicz/PersonalProjects/NL2SQL-agent/backend/venv/lib/python3.11/site-packages/starlette/middleware/base.py", line 78, in call_next
    message = await recv_stream.receive()
              ^^^^^^^^^^^^^^^^^^^^^^^^^^^
  File "/Users/jskuratowicz/PersonalProjects/NL2SQL-agent/backend/venv/lib/python3.11/site-packages/anyio/streams/memory.py", line 98, in receive
    return self.receive_nowait()
           ^^^^^^^^^^^^^^^^^^^^^
  File "/Users/jskuratowicz/PersonalProjects/NL2SQL-agent/backend/venv/lib/python3.11/site-packages/anyio/streams/memory.py", line 91, in receive_nowait
    raise EndOfStream
anyio.EndOfStream

During handling of the above exception, another exception occurred:

Traceback (most recent call last):
  File "/Users/jskuratowicz/PersonalProjects/NL2SQL-agent/backend/venv/lib/python3.11/site-packages/uvicorn/protocols/http/h11_impl.py", line 408, in run_asgi
    result = await app(  # type: ignore[func-returns-value]
             ^^^^^^^^^^^^^^^^^^^^^^^^^^^^^^^^^^^^^^^^^^^^^^
  File "/Users/jskuratowicz/PersonalProjects/NL2SQL-agent/backend/venv/lib/python3.11/site-packages/uvicorn/middleware/proxy_headers.py", line 84, in __call__
    return await self.app(scope, receive, send)
           ^^^^^^^^^^^^^^^^^^^^^^^^^^^^^^^^^^^^
  File "/Users/jskuratowicz/PersonalProjects/NL2SQL-agent/backend/venv/lib/python3.11/site-packages/fastapi/applications.py", line 1106, in __call__
    await super().__call__(scope, receive, send)
  File "/Users/jskuratowicz/PersonalProjects/NL2SQL-agent/backend/venv/lib/python3.11/site-packages/starlette/applications.py", line 122, in __call__
    await self.middleware_stack(scope, receive, send)
  File "/Users/jskuratowicz/PersonalProjects/NL2SQL-agent/backend/venv/lib/python3.11/site-packages/starlette/middleware/errors.py", line 184, in __call__
    raise exc
  File "/Users/jskuratowicz/PersonalProjects/NL2SQL-agent/backend/venv/lib/python3.11/site-packages/starlette/middleware/errors.py", line 162, in __call__
    await self.app(scope, receive, _send)
  File "/Users/jskuratowicz/PersonalProjects/NL2SQL-agent/backend/venv/lib/python3.11/site-packages/starlette/middleware/cors.py", line 91, in __call__
    await self.simple_response(scope, receive, send, request_headers=headers)
  File "/Users/jskuratowicz/PersonalProjects/NL2SQL-agent/backend/venv/lib/python3.11/site-packages/starlette/middleware/cors.py", line 146, in simple_response
    await self.app(scope, receive, send)
  File "/Users/jskuratowicz/PersonalProjects/NL2SQL-agent/backend/venv/lib/python3.11/site-packages/starlette/middleware/base.py", line 108, in __call__
    response = await self.dispatch_func(request, call_next)
               ^^^^^^^^^^^^^^^^^^^^^^^^^^^^^^^^^^^^^^^^^^^^
  File "/Users/jskuratowicz/PersonalProjects/NL2SQL-agent/backend/app/main.py", line 40, in dispatch
    response = await call_next(request)
               ^^^^^^^^^^^^^^^^^^^^^^^^
  File "/Users/jskuratowicz/PersonalProjects/NL2SQL-agent/backend/venv/lib/python3.11/site-packages/starlette/middleware/base.py", line 84, in call_next
    raise app_exc
  File "/Users/jskuratowicz/PersonalProjects/NL2SQL-agent/backend/venv/lib/python3.11/site-packages/starlette/middleware/base.py", line 70, in coro
    await self.app(scope, receive_or_disconnect, send_no_error)
  File "/Users/jskuratowicz/PersonalProjects/NL2SQL-agent/backend/venv/lib/python3.11/site-packages/starlette/middleware/exceptions.py", line 79, in __call__
    raise exc
  File "/Users/jskuratowicz/PersonalProjects/NL2SQL-agent/backend/venv/lib/python3.11/site-packages/starlette/middleware/exceptions.py", line 68, in __call__
    await self.app(scope, receive, sender)
  File "/Users/jskuratowicz/PersonalProjects/NL2SQL-agent/backend/venv/lib/python3.11/site-packages/fastapi/middleware/asyncexitstack.py", line 20, in __call__
    raise e
  File "/Users/jskuratowicz/PersonalProjects/NL2SQL-agent/backend/venv/lib/python3.11/site-packages/fastapi/middleware/asyncexitstack.py", line 17, in __call__
    await self.app(scope, receive, send)
  File "/Users/jskuratowicz/PersonalProjects/NL2SQL-agent/backend/venv/lib/python3.11/site-packages/starlette/routing.py", line 718, in __call__
    await route.handle(scope, receive, send)
  File "/Users/jskuratowicz/PersonalProjects/NL2SQL-agent/backend/venv/lib/python3.11/site-packages/starlette/routing.py", line 276, in handle
    await self.app(scope, receive, send)
  File "/Users/jskuratowicz/PersonalProjects/NL2SQL-agent/backend/venv/lib/python3.11/site-packages/starlette/routing.py", line 66, in app
    response = await func(request)
               ^^^^^^^^^^^^^^^^^^^
  File "/Users/jskuratowicz/PersonalProjects/NL2SQL-agent/backend/venv/lib/python3.11/site-packages/fastapi/routing.py", line 274, in app
    raw_response = await run_endpoint_function(
                   ^^^^^^^^^^^^^^^^^^^^^^^^^^^^
  File "/Users/jskuratowicz/PersonalProjects/NL2SQL-agent/backend/venv/lib/python3.11/site-packages/fastapi/routing.py", line 191, in run_endpoint_function
    return await dependant.call(**values)
           ^^^^^^^^^^^^^^^^^^^^^^^^^^^^^^
  File "/Users/jskuratowicz/PersonalProjects/NL2SQL-agent/backend/app/utils/performance.py", line 51, in wrapper
    result = await func(*args, **kwargs)
             ^^^^^^^^^^^^^^^^^^^^^^^^^^^
  File "/Users/jskuratowicz/PersonalProjects/NL2SQL-agent/backend/app/api/routes.py", line 47, in get_tables
    logger.info(f"Listing tables for demo phase: {demo_phase}", extra={"request_id": request_id})
  File "/Library/Frameworks/Python.framework/Versions/3.11/lib/python3.11/logging/__init__.py", line 1489, in info
    self._log(INFO, msg, args, **kwargs)
  File "/Library/Frameworks/Python.framework/Versions/3.11/lib/python3.11/logging/__init__.py", line 1632, in _log
    record = self.makeRecord(self.name, level, fn, lno, msg, args,
             ^^^^^^^^^^^^^^^^^^^^^^^^^^^^^^^^^^^^^^^^^^^^^^^^^^^^^
  File "/Library/Frameworks/Python.framework/Versions/3.11/lib/python3.11/logging/__init__.py", line 1606, in makeRecord
    raise KeyError("Attempt to overwrite %r in LogRecord" % key)
KeyError: "Attempt to overwrite 'request_id' in LogRecord"
2025-03-10 20:30:57,213 - app.api.routes - ERROR - /Users/jskuratowicz/PersonalProjects/NL2SQL-agent/backend/app/api/routes.py:172 - Failed to generate SQL from question: generate_basic_sql() got an unexpected keyword argument 'table_name'
Traceback (most recent call last):
  File "/Users/jskuratowicz/PersonalProjects/NL2SQL-agent/backend/app/api/routes.py", line 152, in basic_nl2sql
    response = await generate_basic_sql(
               ^^^^^^^^^^^^^^^^^^^^^^^^^
  File "/Users/jskuratowicz/PersonalProjects/NL2SQL-agent/backend/app/utils/performance.py", line 51, in wrapper
    result = await func(*args, **kwargs)
                   ^^^^^^^^^^^^^^^^^^^^^
TypeError: generate_basic_sql() got an unexpected keyword argument 'table_name'
2025-03-10 20:39:09,630 - app.api.routes - ERROR - /Users/jskuratowicz/PersonalProjects/NL2SQL-agent/backend/app/api/routes.py:170 - Failed to generate SQL from question: name 'add_to_query_history' is not defined
Traceback (most recent call last):
  File "/Users/jskuratowicz/PersonalProjects/NL2SQL-agent/backend/app/api/routes.py", line 158, in basic_nl2sql
    add_to_query_history(
    ^^^^^^^^^^^^^^^^^^^^
NameError: name 'add_to_query_history' is not defined
2025-03-11 13:37:14,633 - uvicorn.error - ERROR - /Users/jskuratowicz/PersonalProjects/NL2SQL-agent/backend/venv/lib/python3.11/site-packages/uvicorn/lifespan/on.py:134 - Traceback (most recent call last):
  File "/Users/jskuratowicz/PersonalProjects/NL2SQL-agent/backend/venv/lib/python3.11/site-packages/starlette/routing.py", line 686, in lifespan
    await receive()
  File "/Users/jskuratowicz/PersonalProjects/NL2SQL-agent/backend/venv/lib/python3.11/site-packages/uvicorn/lifespan/on.py", line 137, in receive
    return await self.receive_queue.get()
           ^^^^^^^^^^^^^^^^^^^^^^^^^^^^^^
  File "/Library/Frameworks/Python.framework/Versions/3.11/lib/python3.11/asyncio/queues.py", line 158, in get
    await getter
asyncio.exceptions.CancelledError

